DEBUG:cassandra.connection:Sending options message heartbeat on idle connection (1526857281840) 127.0.0.1:9042
DEBUG:cassandra.connection:Sending options message heartbeat on idle connection (1526856814352) 127.0.0.1:9042
DEBUG:cassandra.connection:Received options response on connection (1526857281840) from 127.0.0.1:9042
DEBUG:cassandra.connection:Received options response on connection (1526856814352) from 127.0.0.1:9042
DEBUG:cassandra.cluster:Connecting to cluster, contact points: ['127.0.0.1']; protocol version: 5
DEBUG:cassandra.io.asyncorereactor:Validated loop dispatch with <class 'cassandra.io.asyncorereactor._BusyWaitDispatcher'>
DEBUG:cassandra.pool:Host 127.0.0.1:9042 is now marked up
DEBUG:cassandra.cluster:[control connection] Opening new connection to 127.0.0.1:9042
DEBUG:cassandra.io.asyncorereactor:Starting asyncore event loop
DEBUG:cassandra.connection:Sending initial options message for new connection (2610781556496) to 127.0.0.1:9042
DEBUG:cassandra.connection:Received options response on new connection (2610781556496) from 127.0.0.1:9042
DEBUG:cassandra.connection:No available compression types supported on both ends. locally supported: odict_keys([]). remotely supported: ['snappy', 'lz4']
DEBUG:cassandra.connection:Sending StartupMessage on <AsyncoreConnection(2610781556496) 127.0.0.1:9042>
DEBUG:cassandra.connection:Sent StartupMessage on <AsyncoreConnection(2610781556496) 127.0.0.1:9042>
DEBUG:cassandra.connection:Got AuthenticateMessage on new connection (2610781556496) from 127.0.0.1:9042: org.apache.cassandra.auth.PasswordAuthenticator
DEBUG:cassandra.connection:Enabling protocol checksumming on connection (2610781556496).
DEBUG:cassandra.connection:Sending SASL-based auth response on <AsyncoreConnection(2610781556496) 127.0.0.1:9042>
DEBUG:cassandra.connection:Connection <AsyncoreConnection(2610781556496) 127.0.0.1:9042> successfully authenticated
DEBUG:cassandra.cluster:[control connection] Established new connection <AsyncoreConnection(2610781556496) 127.0.0.1:9042>, registering watchers and refreshing schema and topology
DEBUG:cassandra.cluster:[control connection] Refreshing node list and token map using preloaded results
INFO:cassandra.policies:Using datacenter 'mumbai' for DCAwareRoundRobinPolicy (via host '127.0.0.1:9042'); if incorrect, please specify a local_dc to the constructor, or limit contact points to local cluster nodes
DEBUG:cassandra.cluster:[control connection] Found new host to connect to: 172.18.0.4:9042
INFO:cassandra.cluster:New Cassandra host <Host: 172.18.0.4:9042 mumbai> discovered
DEBUG:cassandra.cluster:Handling new host <Host: 172.18.0.4:9042 mumbai> and notifying listeners
DEBUG:cassandra.cluster:Done preparing queries for new host <Host: 172.18.0.4:9042 mumbai>
DEBUG:cassandra.pool:Host 172.18.0.4:9042 is now marked up
DEBUG:cassandra.cluster:[control connection] Found new host to connect to: 172.18.0.3:9042
INFO:cassandra.cluster:New Cassandra host <Host: 172.18.0.3:9042 mumbai> discovered
DEBUG:cassandra.cluster:Handling new host <Host: 172.18.0.3:9042 mumbai> and notifying listeners
DEBUG:cassandra.cluster:Done preparing queries for new host <Host: 172.18.0.3:9042 mumbai>
DEBUG:cassandra.pool:Host 172.18.0.3:9042 is now marked up
DEBUG:cassandra.cluster:[control connection] Finished fetching ring info
DEBUG:cassandra.cluster:[control connection] Rebuilding token map due to topology changes
DEBUG:cassandra.cluster:Control connection created
DEBUG:cassandra.pool:Initializing connection for host 127.0.0.1:9042
DEBUG:cassandra.pool:Initializing connection for host 172.18.0.4:9042
DEBUG:cassandra.connection:Sending initial options message for new connection (2610782152640) to 127.0.0.1:9042
DEBUG:cassandra.connection:Received options response on new connection (2610782152640) from 127.0.0.1:9042
DEBUG:cassandra.connection:No available compression types supported on both ends. locally supported: odict_keys([]). remotely supported: ['snappy', 'lz4']
DEBUG:cassandra.connection:Sending StartupMessage on <AsyncoreConnection(2610782152640) 127.0.0.1:9042>
DEBUG:cassandra.connection:Sent StartupMessage on <AsyncoreConnection(2610782152640) 127.0.0.1:9042>
DEBUG:cassandra.connection:Got AuthenticateMessage on new connection (2610782152640) from 127.0.0.1:9042: org.apache.cassandra.auth.PasswordAuthenticator
DEBUG:cassandra.connection:Enabling protocol checksumming on connection (2610782152640).
DEBUG:cassandra.connection:Sending SASL-based auth response on <AsyncoreConnection(2610782152640) 127.0.0.1:9042>
DEBUG:cassandra.connection:Connection <AsyncoreConnection(2610782152640) 127.0.0.1:9042> successfully authenticated
DEBUG:cassandra.pool:Finished initializing connection for host 127.0.0.1:9042
DEBUG:cassandra.cluster:Added pool for host 127.0.0.1:9042 to session
DEBUG:cassandra.pool:Initializing connection for host 172.18.0.3:9042
DEBUG:cassandra.cluster:Not starting MonitorReporter thread for Insights; not supported by server version 4.0.0 on ControlConnection host 127.0.0.1:9042
DEBUG:cassandra.cluster:Started Session with client_id 294fcc7c-6218-483b-8ac3-e13ac2b62caa and session_id 683b589e-726b-48f2-8144-84cf36df98bf
DEBUG:passlib.registry:registered 'bcrypt' handler: <class 'passlib.handlers.bcrypt.bcrypt'>
INFO:uvicorn.error:Started server process [5592]
INFO:uvicorn.error:Waiting for application startup.
INFO:uvicorn.error:Application startup complete.
WARNING:cassandra.cluster:Failed to create connection pool for new host 172.18.0.4:9042:
Traceback (most recent call last):
  File "t:\chi_url\env\lib\site-packages\cassandra\cluster.py", line 3175, in run_add_or_renew_pool
    new_pool = HostConnection(host, distance, self)
  File "t:\chi_url\env\lib\site-packages\cassandra\pool.py", line 402, in __init__
    self._connection = session.cluster.connection_factory(host.endpoint)
  File "t:\chi_url\env\lib\site-packages\cassandra\cluster.py", line 1620, in connection_factory
    return self.connection_class.factory(endpoint, self.connect_timeout, *args, **kwargs)
  File "t:\chi_url\env\lib\site-packages\cassandra\connection.py", line 831, in factory
    conn = cls(endpoint, *args, **kwargs)
  File "t:\chi_url\env\lib\site-packages\cassandra\io\asyncorereactor.py", line 344, in __init__
    self._connect_socket()
  File "t:\chi_url\env\lib\site-packages\cassandra\connection.py", line 898, in _connect_socket
    raise socket.error(sockerr.errno, "Tried connecting to %s. Last error: %s" %
OSError: [Errno None] Tried connecting to [('172.18.0.4', 9042)]. Last error: timed out
WARNING:cassandra.cluster:Host 172.18.0.4:9042 has been marked down
DEBUG:cassandra.cluster:Starting reconnector for host 172.18.0.4:9042
WARNING:cassandra.cluster:Failed to create connection pool for new host 172.18.0.3:9042:
Traceback (most recent call last):
  File "t:\chi_url\env\lib\site-packages\cassandra\cluster.py", line 3175, in run_add_or_renew_pool
    new_pool = HostConnection(host, distance, self)
  File "t:\chi_url\env\lib\site-packages\cassandra\pool.py", line 402, in __init__
    self._connection = session.cluster.connection_factory(host.endpoint)
  File "t:\chi_url\env\lib\site-packages\cassandra\cluster.py", line 1620, in connection_factory
    return self.connection_class.factory(endpoint, self.connect_timeout, *args, **kwargs)
  File "t:\chi_url\env\lib\site-packages\cassandra\connection.py", line 831, in factory
    conn = cls(endpoint, *args, **kwargs)
  File "t:\chi_url\env\lib\site-packages\cassandra\io\asyncorereactor.py", line 344, in __init__
    self._connect_socket()
  File "t:\chi_url\env\lib\site-packages\cassandra\connection.py", line 898, in _connect_socket
    raise socket.error(sockerr.errno, "Tried connecting to %s. Last error: %s" %
OSError: [Errno None] Tried connecting to [('172.18.0.3', 9042)]. Last error: timed out
WARNING:cassandra.cluster:Host 172.18.0.3:9042 has been marked down
DEBUG:cassandra.cluster:Starting reconnector for host 172.18.0.3:9042
WARNING:cassandra.pool:Error attempting to reconnect to 172.18.0.4:9042, scheduling retry in 2.18 seconds: [Errno None] Tried connecting to [('172.18.0.4', 9042)]. Last error: timed out
DEBUG:cassandra.pool:Reconnection error details
Traceback (most recent call last):
  File "t:\chi_url\env\lib\site-packages\cassandra\pool.py", line 278, in run
    conn = self.try_reconnect()
  File "t:\chi_url\env\lib\site-packages\cassandra\pool.py", line 349, in try_reconnect
    return self.connection_factory()
  File "t:\chi_url\env\lib\site-packages\cassandra\connection.py", line 831, in factory
    conn = cls(endpoint, *args, **kwargs)
  File "t:\chi_url\env\lib\site-packages\cassandra\io\asyncorereactor.py", line 344, in __init__
    self._connect_socket()
  File "t:\chi_url\env\lib\site-packages\cassandra\connection.py", line 898, in _connect_socket
    raise socket.error(sockerr.errno, "Tried connecting to %s. Last error: %s" %
OSError: [Errno None] Tried connecting to [('172.18.0.4', 9042)]. Last error: timed out
WARNING:cassandra.pool:Error attempting to reconnect to 172.18.0.3:9042, scheduling retry in 1.86 seconds: [Errno None] Tried connecting to [('172.18.0.3', 9042)]. Last error: timed out
DEBUG:cassandra.pool:Reconnection error details
Traceback (most recent call last):
  File "t:\chi_url\env\lib\site-packages\cassandra\pool.py", line 278, in run
    conn = self.try_reconnect()
  File "t:\chi_url\env\lib\site-packages\cassandra\pool.py", line 349, in try_reconnect
    return self.connection_factory()
  File "t:\chi_url\env\lib\site-packages\cassandra\connection.py", line 831, in factory
    conn = cls(endpoint, *args, **kwargs)
  File "t:\chi_url\env\lib\site-packages\cassandra\io\asyncorereactor.py", line 344, in __init__
    self._connect_socket()
  File "t:\chi_url\env\lib\site-packages\cassandra\connection.py", line 898, in _connect_socket
    raise socket.error(sockerr.errno, "Tried connecting to %s. Last error: %s" %
OSError: [Errno None] Tried connecting to [('172.18.0.3', 9042)]. Last error: timed out
WARNING:cassandra.pool:Error attempting to reconnect to 172.18.0.4:9042, scheduling retry in 3.52 seconds: [Errno None] Tried connecting to [('172.18.0.4', 9042)]. Last error: timed out
DEBUG:cassandra.pool:Reconnection error details
Traceback (most recent call last):
  File "t:\chi_url\env\lib\site-packages\cassandra\pool.py", line 278, in run
    conn = self.try_reconnect()
  File "t:\chi_url\env\lib\site-packages\cassandra\pool.py", line 349, in try_reconnect
    return self.connection_factory()
  File "t:\chi_url\env\lib\site-packages\cassandra\connection.py", line 831, in factory
    conn = cls(endpoint, *args, **kwargs)
  File "t:\chi_url\env\lib\site-packages\cassandra\io\asyncorereactor.py", line 344, in __init__
    self._connect_socket()
  File "t:\chi_url\env\lib\site-packages\cassandra\connection.py", line 898, in _connect_socket
    raise socket.error(sockerr.errno, "Tried connecting to %s. Last error: %s" %
OSError: [Errno None] Tried connecting to [('172.18.0.4', 9042)]. Last error: timed out
WARNING:cassandra.pool:Error attempting to reconnect to 172.18.0.3:9042, scheduling retry in 4.24 seconds: [Errno None] Tried connecting to [('172.18.0.3', 9042)]. Last error: timed out
DEBUG:cassandra.pool:Reconnection error details
Traceback (most recent call last):
  File "t:\chi_url\env\lib\site-packages\cassandra\pool.py", line 278, in run
    conn = self.try_reconnect()
  File "t:\chi_url\env\lib\site-packages\cassandra\pool.py", line 349, in try_reconnect
    return self.connection_factory()
  File "t:\chi_url\env\lib\site-packages\cassandra\connection.py", line 831, in factory
    conn = cls(endpoint, *args, **kwargs)
  File "t:\chi_url\env\lib\site-packages\cassandra\io\asyncorereactor.py", line 344, in __init__
    self._connect_socket()
  File "t:\chi_url\env\lib\site-packages\cassandra\connection.py", line 898, in _connect_socket
    raise socket.error(sockerr.errno, "Tried connecting to %s. Last error: %s" %
OSError: [Errno None] Tried connecting to [('172.18.0.3', 9042)]. Last error: timed out
DEBUG:multipart.multipart:Calling on_field_start with no data
DEBUG:multipart.multipart:Calling on_field_name with data[0:10]
DEBUG:multipart.multipart:Calling on_field_data with data[11:19]
DEBUG:multipart.multipart:Calling on_field_end with no data
DEBUG:multipart.multipart:Calling on_field_start with no data
DEBUG:multipart.multipart:Calling on_field_name with data[20:28]
DEBUG:multipart.multipart:Calling on_field_data with data[29:34]
DEBUG:multipart.multipart:Calling on_field_end with no data
DEBUG:multipart.multipart:Calling on_field_start with no data
DEBUG:multipart.multipart:Calling on_field_name with data[35:43]
DEBUG:multipart.multipart:Calling on_field_data with data[44:48]
DEBUG:multipart.multipart:Calling on_field_end with no data
DEBUG:multipart.multipart:Calling on_end with no data
DEBUG:passlib.handlers.bcrypt:detected 'bcrypt' backend, version '3.2.0'
DEBUG:passlib.handlers.bcrypt:'bcrypt' backend lacks $2$ support, enabling workaround
WARNING:cassandra.pool:Error attempting to reconnect to 172.18.0.4:9042, scheduling retry in 8.48 seconds: [Errno None] Tried connecting to [('172.18.0.4', 9042)]. Last error: timed out
DEBUG:cassandra.pool:Reconnection error details
Traceback (most recent call last):
  File "t:\chi_url\env\lib\site-packages\cassandra\pool.py", line 278, in run
    conn = self.try_reconnect()
  File "t:\chi_url\env\lib\site-packages\cassandra\pool.py", line 349, in try_reconnect
    return self.connection_factory()
  File "t:\chi_url\env\lib\site-packages\cassandra\connection.py", line 831, in factory
    conn = cls(endpoint, *args, **kwargs)
  File "t:\chi_url\env\lib\site-packages\cassandra\io\asyncorereactor.py", line 344, in __init__
    self._connect_socket()
  File "t:\chi_url\env\lib\site-packages\cassandra\connection.py", line 898, in _connect_socket
    raise socket.error(sockerr.errno, "Tried connecting to %s. Last error: %s" %
OSError: [Errno None] Tried connecting to [('172.18.0.4', 9042)]. Last error: timed out
WARNING:cassandra.pool:Error attempting to reconnect to 172.18.0.3:9042, scheduling retry in 8.56 seconds: [Errno None] Tried connecting to [('172.18.0.3', 9042)]. Last error: timed out
DEBUG:cassandra.pool:Reconnection error details
Traceback (most recent call last):
  File "t:\chi_url\env\lib\site-packages\cassandra\pool.py", line 278, in run
    conn = self.try_reconnect()
  File "t:\chi_url\env\lib\site-packages\cassandra\pool.py", line 349, in try_reconnect
    return self.connection_factory()
  File "t:\chi_url\env\lib\site-packages\cassandra\connection.py", line 831, in factory
    conn = cls(endpoint, *args, **kwargs)
  File "t:\chi_url\env\lib\site-packages\cassandra\io\asyncorereactor.py", line 344, in __init__
    self._connect_socket()
  File "t:\chi_url\env\lib\site-packages\cassandra\connection.py", line 898, in _connect_socket
    raise socket.error(sockerr.errno, "Tried connecting to %s. Last error: %s" %
OSError: [Errno None] Tried connecting to [('172.18.0.3', 9042)]. Last error: timed out
WARNING:cassandra.pool:Error attempting to reconnect to 172.18.0.4:9042, scheduling retry in 14.72 seconds: [Errno None] Tried connecting to [('172.18.0.4', 9042)]. Last error: timed out
DEBUG:cassandra.pool:Reconnection error details
Traceback (most recent call last):
  File "t:\chi_url\env\lib\site-packages\cassandra\pool.py", line 278, in run
    conn = self.try_reconnect()
  File "t:\chi_url\env\lib\site-packages\cassandra\pool.py", line 349, in try_reconnect
    return self.connection_factory()
  File "t:\chi_url\env\lib\site-packages\cassandra\connection.py", line 831, in factory
    conn = cls(endpoint, *args, **kwargs)
  File "t:\chi_url\env\lib\site-packages\cassandra\io\asyncorereactor.py", line 344, in __init__
    self._connect_socket()
  File "t:\chi_url\env\lib\site-packages\cassandra\connection.py", line 898, in _connect_socket
    raise socket.error(sockerr.errno, "Tried connecting to %s. Last error: %s" %
OSError: [Errno None] Tried connecting to [('172.18.0.4', 9042)]. Last error: timed out
WARNING:cassandra.pool:Error attempting to reconnect to 172.18.0.3:9042, scheduling retry in 17.44 seconds: [Errno None] Tried connecting to [('172.18.0.3', 9042)]. Last error: timed out
DEBUG:cassandra.pool:Reconnection error details
Traceback (most recent call last):
  File "t:\chi_url\env\lib\site-packages\cassandra\pool.py", line 278, in run
    conn = self.try_reconnect()
  File "t:\chi_url\env\lib\site-packages\cassandra\pool.py", line 349, in try_reconnect
    return self.connection_factory()
  File "t:\chi_url\env\lib\site-packages\cassandra\connection.py", line 831, in factory
    conn = cls(endpoint, *args, **kwargs)
  File "t:\chi_url\env\lib\site-packages\cassandra\io\asyncorereactor.py", line 344, in __init__
    self._connect_socket()
  File "t:\chi_url\env\lib\site-packages\cassandra\connection.py", line 898, in _connect_socket
    raise socket.error(sockerr.errno, "Tried connecting to %s. Last error: %s" %
OSError: [Errno None] Tried connecting to [('172.18.0.3', 9042)]. Last error: timed out
DEBUG:multipart.multipart:Calling on_field_start with no data
DEBUG:multipart.multipart:Calling on_field_name with data[0:10]
DEBUG:multipart.multipart:Calling on_field_data with data[11:19]
DEBUG:multipart.multipart:Calling on_field_end with no data
DEBUG:multipart.multipart:Calling on_field_start with no data
DEBUG:multipart.multipart:Calling on_field_name with data[20:28]
DEBUG:multipart.multipart:Calling on_field_data with data[29:34]
DEBUG:multipart.multipart:Calling on_field_end with no data
DEBUG:multipart.multipart:Calling on_field_start with no data
DEBUG:multipart.multipart:Calling on_field_name with data[35:43]
DEBUG:multipart.multipart:Calling on_field_data with data[44:48]
DEBUG:multipart.multipart:Calling on_field_end with no data
DEBUG:multipart.multipart:Calling on_end with no data
DEBUG:cassandra.connection:Sending options message heartbeat on idle connection (2610781556496) 127.0.0.1:9042
DEBUG:cassandra.connection:Received options response on connection (2610781556496) from 127.0.0.1:9042
WARNING:cassandra.pool:Error attempting to reconnect to 172.18.0.4:9042, scheduling retry in 32.64 seconds: [Errno None] Tried connecting to [('172.18.0.4', 9042)]. Last error: timed out
DEBUG:cassandra.pool:Reconnection error details
Traceback (most recent call last):
  File "t:\chi_url\env\lib\site-packages\cassandra\pool.py", line 278, in run
    conn = self.try_reconnect()
  File "t:\chi_url\env\lib\site-packages\cassandra\pool.py", line 349, in try_reconnect
    return self.connection_factory()
  File "t:\chi_url\env\lib\site-packages\cassandra\connection.py", line 831, in factory
    conn = cls(endpoint, *args, **kwargs)
  File "t:\chi_url\env\lib\site-packages\cassandra\io\asyncorereactor.py", line 344, in __init__
    self._connect_socket()
  File "t:\chi_url\env\lib\site-packages\cassandra\connection.py", line 898, in _connect_socket
    raise socket.error(sockerr.errno, "Tried connecting to %s. Last error: %s" %
OSError: [Errno None] Tried connecting to [('172.18.0.4', 9042)]. Last error: timed out
WARNING:cassandra.pool:Error attempting to reconnect to 172.18.0.3:9042, scheduling retry in 30.72 seconds: [Errno None] Tried connecting to [('172.18.0.3', 9042)]. Last error: timed out
DEBUG:cassandra.pool:Reconnection error details
Traceback (most recent call last):
  File "t:\chi_url\env\lib\site-packages\cassandra\pool.py", line 278, in run
    conn = self.try_reconnect()
  File "t:\chi_url\env\lib\site-packages\cassandra\pool.py", line 349, in try_reconnect
    return self.connection_factory()
  File "t:\chi_url\env\lib\site-packages\cassandra\connection.py", line 831, in factory
    conn = cls(endpoint, *args, **kwargs)
  File "t:\chi_url\env\lib\site-packages\cassandra\io\asyncorereactor.py", line 344, in __init__
    self._connect_socket()
  File "t:\chi_url\env\lib\site-packages\cassandra\connection.py", line 898, in _connect_socket
    raise socket.error(sockerr.errno, "Tried connecting to %s. Last error: %s" %
OSError: [Errno None] Tried connecting to [('172.18.0.3', 9042)]. Last error: timed out
DEBUG:cassandra.connection:Sending options message heartbeat on idle connection (2610782152640) 127.0.0.1:9042
DEBUG:cassandra.connection:Sending options message heartbeat on idle connection (2610781556496) 127.0.0.1:9042
DEBUG:cassandra.connection:Received options response on connection (2610781556496) from 127.0.0.1:9042
DEBUG:cassandra.connection:Received options response on connection (2610782152640) from 127.0.0.1:9042
INFO:uvicorn.error:Shutting down
INFO:uvicorn.error:Waiting for application shutdown.
